<?xml version="1.0" ?>
<!-- =================================================================================== -->
<!-- |    This document was autogenerated by xacro from /home/kiri/kiri_ws/src/kiri_description/urdf/kiri.xacro | -->
<!-- |    EDITING THIS FILE BY HAND IS NOT RECOMMENDED                                 | -->
<!-- =================================================================================== -->
<robot name="kiri">
    <material name="silver">
        <color rgba="0.700 0.700 0.700 1.000" />
    </material>
    <link name="world" />
    <link name="base_link">
        <inertial>
            <origin rpy="0 0 0" xyz="-8.76585590771171e-09 4.625245772864268e-06 0.07417200620727467" />
            <mass value="0.9675774171477199" />
            <inertia ixx="0.003719" ixy="0.0" ixz="-0.0" iyy="0.00372" iyz="0.0" izz="0.004249" />
        </inertial>
        <visual>
            <origin rpy="0 0 0" xyz="0 0 0" />
            <geometry>
                <mesh filename="package://kiri_description/meshes/base_link.stl" scale="0.001 0.001 0.001" />
            </geometry>
            <material name="silver" />
        </visual>
        <collision>
            <origin rpy="0 0 0" xyz="0 0 0" />
            <geometry>
                <mesh filename="package://kiri_description/meshes/base_link.stl" scale="0.001 0.001 0.001" />
            </geometry>
        </collision>
    </link>
    <link name="link_1">
        <inertial>
            <origin rpy="0 0 0" xyz="0.027954074838879572 1.2774374489140266e-05 0.05220058358440388" />
            <mass value="5.26595321272139" />
            <inertia ixx="0.010161" ixy="-3e-06" ixz="-0.002233" iyy="0.013402" iyz="-4e-06" izz="0.010957" />
        </inertial>
        <visual>
            <origin rpy="0 0 0" xyz="-0.0 -0.0 -0.1325" />
            <geometry>
                <mesh filename="package://kiri_description/meshes/link_1_1.stl" scale="0.001 0.001 0.001" />
            </geometry>
            <material name="silver" />
        </visual>
        <collision>
            <origin rpy="0 0 0" xyz="-0.0 -0.0 -0.1325" />
            <geometry>
                <mesh filename="package://kiri_description/meshes/link_1_1.stl" scale="0.001 0.001 0.001" />
            </geometry>
        </collision>
    </link>
    <link name="link_2">
        <inertial>
            <origin rpy="0 0 0" xyz="-0.009366936381685993 6.552889280308437e-05 0.08684357826941763" />
            <mass value="4.755056928672819" />
            <inertia ixx="0.021197" ixy="4.7e-05" ixz="0.000291" iyy="0.02322" iyz="-2.2e-05" izz="0.006427" />
        </inertial>
        <visual>
            <origin rpy="0 0 0" xyz="0.01214 -3.7e-05 -0.201" />
            <geometry>
                <mesh filename="package://kiri_description/meshes/link_2_1.stl" scale="0.001 0.001 0.001" />
            </geometry>
            <material name="silver" />
        </visual>
        <collision>
            <origin rpy="0 0 0" xyz="0.01214 -3.7e-05 -0.201" />
            <geometry>
                <mesh filename="package://kiri_description/meshes/link_2_1.stl" scale="0.001 0.001 0.001" />
            </geometry>
        </collision>
    </link>
    <link name="link_3">
        <inertial>
            <origin rpy="0 0 0" xyz="0.03367813638240873 0.028072928800892603 0.04634723991153877" />
            <mass value="2.137433390159692" />
            <inertia ixx="0.003913" ixy="-0.000494" ixz="-0.000816" iyy="0.003043" iyz="-0.000544" izz="0.003902" />
        </inertial>
        <visual>
            <origin rpy="0 0 0" xyz="0.01214 -3.7e-05 -0.381" />
            <geometry>
                <mesh filename="package://kiri_description/meshes/link_3_1.stl" scale="0.001 0.001 0.001" />
            </geometry>
            <material name="silver" />
        </visual>
        <collision>
            <origin rpy="0 0 0" xyz="0.01214 -3.7e-05 -0.381" />
            <geometry>
                <mesh filename="package://kiri_description/meshes/link_3_1.stl" scale="0.001 0.001 0.001" />
            </geometry>
        </collision>
    </link>
    <link name="link_4">
        <inertial>
            <origin rpy="0 0 0" xyz="-0.005245756214767468 -0.056889563309725236 -5.6206564455152375e-05" />
            <mass value="1.9217220636356325" />
            <inertia ixx="0.002413" ixy="-0.0003" ixz="2e-06" iyy="0.001547" iyz="2e-06" izz="0.003204" />
        </inertial>
        <visual>
            <origin rpy="0 0 0" xyz="-0.02986 0.018433 -0.43675" />
            <geometry>
                <mesh filename="package://kiri_description/meshes/link_4_1.stl" scale="0.001 0.001 0.001" />
            </geometry>
            <material name="silver" />
        </visual>
        <collision>
            <origin rpy="0 0 0" xyz="-0.02986 0.018433 -0.43675" />
            <geometry>
                <mesh filename="package://kiri_description/meshes/link_4_1.stl" scale="0.001 0.001 0.001" />
            </geometry>
        </collision>
    </link>
    <link name="link_5">
        <inertial>
            <origin rpy="0 0 0" xyz="-0.02975423901507546 -0.017700782594158415 0.001500343163774176" />
            <mass value="1.2304142348959926" />
            <inertia ixx="0.000652" ixy="1.7e-05" ixz="-2e-06" iyy="0.000572" iyz="-2.5e-05" izz="0.000763" />
        </inertial>
        <visual>
            <origin rpy="0 0 0" xyz="-0.059857 0.131028 -0.436864" />
            <geometry>
                <mesh filename="package://kiri_description/meshes/link_5_1.stl" scale="0.001 0.001 0.001" />
            </geometry>
            <material name="silver" />
        </visual>
        <collision>
            <origin rpy="0 0 0" xyz="-0.059857 0.131028 -0.436864" />
            <geometry>
                <mesh filename="package://kiri_description/meshes/link_5_1.stl" scale="0.001 0.001 0.001" />
            </geometry>
        </collision>
    </link>
    <link name="link_6">
        <inertial>
            <origin rpy="0 0 0" xyz="-1.1845311122249402e-07 -0.03229549388067854 0.0018281416085541013" />
            <mass value="1.142196425861989" />
            <inertia ixx="0.00069" ixy="-0.0" ixz="0.0" iyy="0.000536" iyz="2.4e-05" izz="0.00084" />
        </inertial>
        <visual>
            <origin rpy="0 0 0" xyz="-0.030903 0.183096 -0.43675" />
            <geometry>
                <mesh filename="package://kiri_description/meshes/link_6_1.stl" scale="0.001 0.001 0.001" />
            </geometry>
            <material name="silver" />
        </visual>
        <collision>
            <origin rpy="0 0 0" xyz="-0.030903 0.183096 -0.43675" />
            <geometry>
                <mesh filename="package://kiri_description/meshes/link_6_1.stl" scale="0.001 0.001 0.001" />
            </geometry>
        </collision>
    </link>
    <link name="link_7">
        <inertial>
            <origin rpy="0 0 0" xyz="-0.004921350215667475 -0.02368454863036701 -0.0017992160930257461" />
            <mass value="0.029227804912521096" />
            <inertia ixx="7e-06" ixy="-2e-06" ixz="0.0" iyy="1e-06" iyz="0.0" izz="8e-06" />
        </inertial>
        <visual>
            <origin rpy="0 0 0" xyz="-0.045903 0.245346 -0.439385" />
            <geometry>
                <mesh filename="package://kiri_description/meshes/link_7_1.stl" scale="0.001 0.001 0.001" />
            </geometry>
            <material name="silver" />
        </visual>
        <collision>
            <origin rpy="0 0 0" xyz="-0.045903 0.245346 -0.439385" />
            <geometry>
                <mesh filename="package://kiri_description/meshes/link_7_1.stl" scale="0.001 0.001 0.001" />
            </geometry>
        </collision>
    </link>
    <link name="link_8">
        <inertial>
            <origin rpy="0 0 0" xyz="0.004921201365448383 -0.02368448005660495 -0.0017992095033099176" />
            <mass value="0.029227870763449907" />
            <inertia ixx="7e-06" ixy="2e-06" ixz="-0.0" iyy="1e-06" iyz="0.0" izz="8e-06" />
        </inertial>
        <visual>
            <origin rpy="0 0 0" xyz="-0.015903 0.245346 -0.439385" />
            <geometry>
                <mesh filename="package://kiri_description/meshes/link_8_1.stl" scale="0.001 0.001 0.001" />
            </geometry>
            <material name="silver" />
        </visual>
        <collision>
            <origin rpy="0 0 0" xyz="-0.015903 0.245346 -0.439385" />
            <geometry>
                <mesh filename="package://kiri_description/meshes/link_8_1.stl" scale="0.001 0.001 0.001" />
            </geometry>
        </collision>
    </link>
    <joint name="base_joint" type="fixed">
        <parent link="world" />
        <child link="base_link" />
        <origin rpy="0 0 0" xyz="0.0 0.0 0.0" />
    </joint>
    <joint name="joint_1" type="revolute">
        <origin rpy="0 0 0" xyz="0.0 0.0 0.1325" />
        <parent link="base_link" />
        <child link="link_1" />
        <axis xyz="0.0 0.0 1.0" />
        <limit effort="100" lower="0.0" upper="3.141593" velocity="100" />
    </joint>
    <joint name="joint_2" type="revolute">
        <origin rpy="0 0 0" xyz="-0.01214 3.7e-05 0.0685" />
        <parent link="link_1" />
        <child link="link_2" />
        <axis xyz="1.0 -0.0 -0.0" />
        <limit effort="100" lower="-1.570796" upper="1.570796" velocity="100" />
    </joint>
    <joint name="joint_3" type="revolute">
        <origin rpy="0 0 0" xyz="0.0 0.0 0.18" />
        <parent link="link_2" />
        <child link="link_3" />
        <axis xyz="-1.0 0.0 -0.0" />
        <limit effort="100" lower="-1.396263" upper="1.570796" velocity="100" />
    </joint>
    <joint name="joint_4" type="revolute">
        <origin rpy="0 0 0" xyz="0.042 -0.01847 0.05575" />
        <parent link="link_3" />
        <child link="link_4" />
        <axis xyz="0.0 -1.0 -0.0" />
        <limit effort="100" lower="-1.570796" upper="1.570796" velocity="100" />
    </joint>
    <joint name="joint_5" type="revolute">
        <origin rpy="0 0 0" xyz="0.029997 -0.112595 0.000114" />
        <parent link="link_4" />
        <child link="link_5" />
        <axis xyz="-1.0 0.0 -0.0" />
        <limit effort="100" lower="-1.745329" upper="1.745329" velocity="100" />
    </joint>
    <joint name="joint_6" type="revolute">
        <origin rpy="0 0 0" xyz="-0.028954 -0.052068 -0.000114" />
        <parent link="link_5" />
        <child link="link_6" />
        <axis xyz="-0.0 -1.0 0.0" />
        <limit effort="100" lower="-1.570796" upper="1.570796" velocity="100" />
    </joint>
    <joint name="joint_7" type="revolute">
        <origin rpy="0 0 0" xyz="0.015 -0.06225 0.002635" />
        <parent link="link_6" />
        <child link="link_7" />
        <axis xyz="-0.0 -0.0 1.0" />
        <limit effort="100" lower="0.0" upper="1.570796" velocity="100" />
    </joint>
    <joint name="joint_8" type="revolute">
        <origin rpy="0 0 0" xyz="-0.015 -0.06225 0.002635" />
        <parent link="link_6" />
        <child link="link_8" />
        <axis xyz="0.0 -0.0 1.0" />
        <limit effort="100" lower="-1.570796" upper="0.0" velocity="100" />
    </joint>
    <transmission name="joint_1_tran">
        <type>transmission_interface/SimpleTransmission</type>
        <joint name="joint_1">
            <hardwareInterface>hardware_interface/PositionJointInterface</hardwareInterface>
        </joint>
        <actuator name="joint_1_motor">
            <hardwareInterface>hardware_interface/PositionJointInterface</hardwareInterface>
            <mechanicalReduction>1</mechanicalReduction>
        </actuator>
    </transmission>
    <transmission name="joint_2_tran">
        <type>transmission_interface/SimpleTransmission</type>
        <joint name="joint_2">
            <hardwareInterface>hardware_interface/PositionJointInterface</hardwareInterface>
        </joint>
        <actuator name="joint_2_motor">
            <hardwareInterface>hardware_interface/PositionJointInterface</hardwareInterface>
            <mechanicalReduction>1</mechanicalReduction>
        </actuator>
    </transmission>
    <transmission name="joint_3_tran">
        <type>transmission_interface/SimpleTransmission</type>
        <joint name="joint_3">
            <hardwareInterface>hardware_interface/PositionJointInterface</hardwareInterface>
        </joint>
        <actuator name="joint_3_motor">
            <hardwareInterface>hardware_interface/PositionJointInterface</hardwareInterface>
            <mechanicalReduction>1</mechanicalReduction>
        </actuator>
    </transmission>
    <transmission name="joint_4_tran">
        <type>transmission_interface/SimpleTransmission</type>
        <joint name="joint_4">
            <hardwareInterface>hardware_interface/PositionJointInterface</hardwareInterface>
        </joint>
        <actuator name="joint_4_motor">
            <hardwareInterface>hardware_interface/PositionJointInterface</hardwareInterface>
            <mechanicalReduction>1</mechanicalReduction>
        </actuator>
    </transmission>
    <transmission name="joint_5_tran">
        <type>transmission_interface/SimpleTransmission</type>
        <joint name="joint_5">
            <hardwareInterface>hardware_interface/PositionJointInterface</hardwareInterface>
        </joint>
        <actuator name="joint_5_motor">
            <hardwareInterface>hardware_interface/PositionJointInterface</hardwareInterface>
            <mechanicalReduction>1</mechanicalReduction>
        </actuator>
    </transmission>
    <transmission name="joint_6_tran">
        <type>transmission_interface/SimpleTransmission</type>
        <joint name="joint_6">
            <hardwareInterface>hardware_interface/PositionJointInterface</hardwareInterface>
        </joint>
        <actuator name="joint_6_motor">
            <hardwareInterface>hardware_interface/PositionJointInterface</hardwareInterface>
            <mechanicalReduction>1</mechanicalReduction>
        </actuator>
    </transmission>
    <transmission name="joint_7_tran">
        <type>transmission_interface/SimpleTransmission</type>
        <joint name="joint_7">
            <hardwareInterface>hardware_interface/PositionJointInterface</hardwareInterface>
        </joint>
        <actuator name="joint_7_motor">
            <hardwareInterface>hardware_interface/PositionJointInterface</hardwareInterface>
            <mechanicalReduction>1</mechanicalReduction>
        </actuator>
    </transmission>
    <transmission name="joint_8_tran">
        <type>transmission_interface/SimpleTransmission</type>
        <joint name="joint_8">
            <hardwareInterface>hardware_interface/PositionJointInterface</hardwareInterface>
        </joint>
        <actuator name="joint_8_motor">
            <hardwareInterface>hardware_interface/PositionJointInterface</hardwareInterface>
            <mechanicalReduction>1</mechanicalReduction>
        </actuator>
    </transmission>
    <gazebo>
        <plugin filename="libgazebo_ros_control.so" name="control">
            <robotNamespace>/</robotNamespace>
        </plugin>
        <plugin name="gazebo_ros_control">
            <robotNamespace>/</robotNamespace>
        </plugin>
    </gazebo>
    <gazebo reference="link_1">
        <selfCollide>true</selfCollide>
    </gazebo>
    <gazebo reference="link_2">
        <selfCollide>true</selfCollide>
    </gazebo>
    <gazebo reference="link_3">
        <selfCollide>true</selfCollide>
    </gazebo>
    <gazebo reference="link_4">
        <selfCollide>true</selfCollide>
    </gazebo>
    <gazebo reference="link_5">
        <selfCollide>true</selfCollide>
    </gazebo>
    <gazebo reference="link_6">
        <selfCollide>true</selfCollide>
    </gazebo>
    <gazebo reference="link_7">
        <selfCollide>false</selfCollide>
    </gazebo>
    <gazebo reference="link_8">
        <selfCollide>false</selfCollide>
    </gazebo>
</robot>

